Workbook

Sheet Исходные данне
B1: Исходные данные
A3: № | B3: Статья | C3: Ед. изм. | E3: Стоимость, рубль | F3: Источник данных | G3: Формула / пояснение
B4: 1. Оборудование (CapEx, на 1 магазин)
A5: 1.1 | B5: Сервер локальный (backroom) | C5: шт. | E5: 120000 | F5: Оценка на основе рыночных цен на серверы для ритейла (аналоги: DEPO, Aquarius) | G5: AS-IS: сервер в подсобке с MS SQL Express. В TO-BE ликвидируется.
A6: 1.2 | B6: MS SQL Express | C6: шт. | E6: 0 | F6: бесплатный, лицензия не нужна | G6: AS-IS
A7: 1.3 | B7: Windows Server Standard (лицензия) | C7: шт. | E7: 65000 | F7: Реестр Минцифры: аналог — Astra Linux Server, 65 000 ₽ | G7: AS-IS: лицензия на каждый сервер. В TO-BE не требуется.
A8: 1.4 | B8: POS-компьютер / моноблок | C8: шт. | E8: 36500 | F8: Цена на АТОЛ Optima V7 Lite | G8: AS-IS: толстый клиент. В TO-BE заменяется на планшет.
A9: 1.5 | B9: Планшет (Cloud POS) | C9: шт. | E9: 25000 | F9: Оценка российских планшетов (Digma, F+, Irbis) для ритейла | G9: TO-BE: тонкий клиент, PWA. 1 шт. на кассу.
A10: 1.6 | B10: Фискальный регистратор (ККТ) | C10: шт. | E10: 46330 | F10: ККТ «РР-01Ф» с ФН15 | G10: Сохраняется в обоих сценариях. Драйвер изолируется в HAL.
A11: 1.7 | B11: Фискальный накопитель (ФН-15) | C11: шт. | E11: 9200 | F11: Аренда кассы АТОЛ | G11: Замена каждые 15 месяцев.
A12: 1.8 | B12: Edge Node (HAL Agent) | C12: шт. | E12: 35000 | F12: Оценка российских mini-PC (Аквариус, ICL) | G12: TO-BE: локальный агент HAL. 1 шт. на магазин.
A13: 1.9 | B13: Банковский терминал | C13: шт. | E13: 25000 | F13: Средняя цена российских терминалов (Сбер, ВТБ, Альфа) | G13: Остаётся в обоих сценариях. Абстрагируется через Payment Gateway.
B15: 2. Лицензии и подписки (OpEx)
A16: 2.1 | B16: Windows Server (продление SA) | C16: год | E16: 13000 | F16: 20% от CapEx лицензии | G16: AS-IS: Software Assurance. В TO-BE не требуется.
A17: 2.3 | B17: Payment Gateway (подписка) | C17: мес. (backend) | E17: 2500 | F17: Оценка SaaS Payment Gateway для ритейла | G17: TO-BE: абстракция терминалов.
A18: 2.4 | B18: ITSM / Monitoring (SaaS) | C18: мес. | E18: 1500 | F18: Оценка ServiceNow / Datadog для ритейла | G18: TO-BE: proactive support.
A19: 2.5 | B19: Managed PostgreSQL | C19: мес. (backend) | E19: 1274 | F19: MWS Managed PostgreSQL 1 vCPU General (1 273,68 ₽/мес) | G19: TO-BE: замена локального MS SQL.
A20: 2.6 | B20: Managed Kafka | C20: мес. (backend) | E20: 1186 | F20: MWS Managed Apache Kafka 1 vCPU General | G20: TO-BE: event-driven шина.
A21: 2.7 | B21: Managed Redis | C21: мес. (backend) | E21: 500 | F21: Оценка managed Redis в российском облаке | G21: TO-BE: кэш справочников и цен.
B23: 3. ФОТ поддержки (OpEx, на 1 магазин / год)
A24: 3.1 | B24: ИТ-инженер (выездной) | C24: час | E24: 2500 | F24: Аутстаффинг Senior от 2 500 ₽/час | G24: AS-IS: выезды для настройки и ремонта. В TO-BE — zero-touch.
A25: 3.2 | B25: ИТ-инженер (удалённая поддержка) | C25: час | E25: 1800 | F25: Аутстаффинг Middle от 1 800 ₽/час | G25: TO-BE: централизованная поддержка.
A26: 3.3 | B26: Товаровед (HQ) | C26: час | E26: 500 | F26: Медиана зарплаты товароведа 90 000 ₽/мес | G26: ФОТ = 90 000 / 176 часов = 511 ₽/час. Округлено до 500 ₽.
A27: 3.4 | B27: ИТ-директор (доля на магазин) | C27: год | E27: 15000 | F27: 1 ИТ-директор на 100 магазинов | G27: Распределённая стоимость.
A28: 3.5 | B28: Стоимость 1 FTE поддержки | C28: мес. | E28: 150000 | F28: hh.ru, Хабр Карьера + 30% на налоги и накладные | G28: Полная стоимость сотрудника: оклад (~110 000) + НДФЛ и взносы (~30 000) + рабочее место (~10 000).
B30: 3a. Количественные показатели ФОТ
A31: 3а.1 | B31: Количество FTE (AS-IS) | C31: чел | D31: 3
A32: 3а.2 | B32: Количество FTE (TO-BE) | C32: чел | D32: 2
A33: 3а.3 | B33: Горизонт | C33: мес | D33: 12
B35: 4. Трудозатраты на онбординг (на 1 магазин)
A36: 4.1 | B36: Выезд ИТ-инженера (AS-IS) | C36: час | E36: 2500 | F36: Артефакт-2: выезд, снятие дампа | G36: 2 дня × 8 часов.
A37: 4.2 | B37: Командировочные расходы (AS-IS) | C37: поездка | E37: 25000 | F37: Оценка: авиабилет + гостиница + суточные | G37: AS-IS: выезд в регион.
A38: 4.3 | B38: Ручной маппинг SKU (AS-IS) | C38: час | E38: 500 | F38: Артефакт-4: 80% вручную, 10 000 позиций | G38: 10 000 позиций / 500 позиций в час = 20 часов.
A39: 4.4 | B39: Ручной маппинг SKU (TO-BE) | C39: час | E39: 500 | F39: Целевое: 80% автоматизации | G39: 20 часов × 20% = 4 часа верификации.
A40: 4.5 | B40: Обучение персонала (ставка) | C40: час | E40: 1500 | F40: Оценка: 1 день обучения кассиров Актуальная ставка внешнего тренера Middle на SkillStaff — 1 428 ₽/час. Если обучение проводит внешний тренер, значение нужно увеличить. Округляем до 1 500 р/час | G40: 8 часов × стоимость часа обучения.
B44: 5. Стоимость облачных ресурсов (TO-BE)
A45: 5.1 | B45: Виртуальные машины (Cloud Backend) | C45: мес. | E45: 4500 | F45: Yandex Cloud: VM 2vCPU/4GB от 4 500 ₽/мес | G45: 5 VM для Cloud POS, Sync, Loyalty, AI.
A46: 5.2 | B46: Объектное хранилище (бэкапы) | C46: ТБ / мес. | D46: 5 | E46: 500 | F46: Оценка Selectel / Yandex Cloud | G46: 5 ТБ × 500 ₽/ТБ.
A47: 5.3 | B47: API Gateway | C47: мес. | E47: 15000 | F47: Оценка Kong / российский аналог | G47: Общая инфраструктура.
A48: 5.4 | B48: iPaaS (Data Integration) | C48: мес. | E48: 50000 | F48: Оценка MuleSoft / Boomi для ритейла | G48: Общая инфраструктура.
...

Sheet Расчёт остаточной стоимости
A1: Расчёт остаточной стоимости
A2: Таблица 1. AS-IS — на 1 магазин (₽)
A3: № | B3: Позиция | C3: Первоначальная | D3: Конец Года 1 (70%) | E3: Конец Года 2 (45%) | F3: Конец Года 3 (15%)
A4: 1 | B4: Сервер локальный | C4: ='Исходные данне'!E5 -> 120000 | D4: =C4*0.7 -> 84000 | E4: =C4*0.45 -> 54000 | F4: =C4*0.15 -> 18000
A5: 2 | B5: POS-компьютер | C5: ='Исходные данне'!E8 -> 36500 | D5: =C5*0.7 -> 25550 | E5: =C5*0.45 -> 16425 | F5: =C5*0.15 -> 5475
A6: 3 | B6: Фискальный регистратор (ККТ) | C6: ='Исходные данне'!E10 -> 46330 | D6: =C6*0.7 -> 32431 | E6: =C6*0.45 -> 20848.5 | F6: =C6*0.15 -> 6949.5
A7: 4 | B7: Банковский терминал | C7: ='Исходные данне'!E13 -> 25000 | D7: =C7*0.7 -> 17500 | E7: =C7*0.45 -> 11250 | F7: =C7*0.15 -> 3750
B8: ИТОГО на 1 магазин | C8: =SUM(C4:C7) -> 227830 | D8: =SUM(D4:D7) -> 159481 | E8: =SUM(E4:E7) -> 102523.5 | F8: =SUM(F4:F7) -> 34174.5
A13: Таблица 3. TO-BE — на 1 магазин (₽)
A14: № | B14: Позиция | C14: Первоначальная | D14: Конец Года 1 (70%) | E14: Конец Года 2 (45%) | F14: Конец Года 3 (15%)
A15: 1 | B15: Планшет (Cloud POS) | C15: ='Исходные данне'!E9 -> 25000 | D15: =C15*0.7 -> 17500 | E15: =C15*0.45 -> 11250 | F15: =C15*0.15 -> 3750
A16: 2 | B16: Фискальный регистратор (ККТ) | C16: ='Исходные данне'!E10 -> 46330 | D16: =C16*0.7 -> 32431 | E16: =C16*0.45 -> 20848.5 | F16: =C16*0.15 -> 6949.5
A17: 3 | B17: Edge Node (HAL Agent) | C17: ='Исходные данне'!E12 -> 35000 | D17: =C17*0.7 -> 24500 | E17: =C17*0.45 -> 15750 | F17: =C17*0.15 -> 5250
A18: 4 | B18: Банковский терминал | C18: ='Исходные данне'!E13 -> 25000 | D18: =C18*0.7 -> 17500 | E18: =C18*0.45 -> 11250 | F18: =C18*0.15 -> 3750
B19: ИТОГО на 1 магазин | C19: 139330 | D19: 97531 | E19: 62699 | F19: 20900

Sheet AS-IS — TCO за 3 года
A1: TCO AS-IS | B1: Количество магазинов | G1: 100
A3: № | B3: Категория | C3: Год 1 | D3: Год 2 | E3: Год 3 | F3: Итого | G3: Источник данных
A4: 1 | B4: CapEx: Оборудование | C4: =SUM(C5:C9) -> 23703000 | D4: =SUM(D5:D9) -> 0 | E4: =SUM(E5:E9) -> 0 | F4: =SUM(C4:E4) -> 23703000 | G4: Шаг 1, раздел 1
A5: 46023 | B5: — серверы локальные | C5: ='Исходные данне'!E5*$G$1 -> 12000000 | F5: =SUM(C5:E5) -> 12000000 | G5: Оценка рынка (DEPO, Aquarius)
A6: 46054 | B6: — POS-компьютеры | C6: ='Исходные данне'!E8*G1 -> 3650000 | F6: =SUM(C6:E6) -> 3650000 | G6: АТОЛ Optima V7 Lite
A7: 46082 | B7: — фискальные регистраторы | C7: ='Исходные данне'!E10*G1 -> 4633000 | F7: =SUM(C7:E7) -> 4633000 | G7: ККТ «РР-01Ф» с ФН15
A8: 46113 | B8: — фискальные накопители | C8: ='Исходные данне'!E11*G1 -> 920000 | F8: =SUM(C8:E8) -> 920000 | G8: Аренда кассы АТОЛ
A9: 46143 | B9: — банковские терминалы | C9: ='Исходные данне'!E13*G1 -> 2500000 | F9: =SUM(C9:E9) -> 2500000 | G9: Средняя цена (Сбер, ВТБ, Альфа)
A11: 2 | B11: CapEx: Лицензии | C11: =SUM(C12:C12) -> 6500000 | D11: =SUM(D12:D12) -> 0 | E11: =SUM(E12:E12) -> 0 | F11: =SUM(C11:E11) -> 6500000 | G11: Реестр Минцифры
A12: 46024 | B12: Windows Server | C12: ='Исходные данне'!E7*G1 -> 6500000 | F12: =SUM(C12:E12) -> 6500000 | G12: Аналог Astra Linux Server
A14: 3 | B14: OpEx: Лицензии (SA) | C14: =SUM(C15:C15) -> 1300000 | D14: =SUM(D15:D15) -> 1300000 | E14: =SUM(E15:E15) -> 1300000 | F14: =SUM(C14:E14) -> 3900000 | G14: 20% от CapEx лицензий
A15: 46025 | B15: — Windows Server (продление SA) | C15: ='Исходные данне'!E16*G1 -> 1300000 | D15: =C15 -> 1300000 | E15: =D15 -> 1300000 | F15: =SUM(C15:E15) -> 3900000
A17: 4 | B17: OpEx: ФОТ онбординга | C17: =SUM(C18:C21) -> 8700000 | D17: =SUM(D18:D21) -> 0 | E17: =SUM(E18:E21) -> 0 | F17: =SUM(C17:E17) -> 8700000 | G17: Шаг 1, раздел 4 + Артефакт-2, 4
A18: 46026 | B18: — выезд ИТ-инженера | C18: ='Исходные данне'!E24*16*G1 -> 4000000 | F18: =SUM(C18:E18) -> 4000000 | G18: Аутстаффинг Senior 2 500 ₽/ч
A19: 46057 | B19: — командировочные | C19: ='Исходные данне'!E37*G1 -> 2500000 | F19: =SUM(C19:E19) -> 2500000 | G19: Оценка (авиа + гостиница + суточные)
A20: 46085 | B20: — ручной маппинг SKU | C20: =G1*'Исходные данне'!E26*20 -> 1000000 | F20: =SUM(C20:E20) -> 1000000 | G20: Артефакт-4 (500 поз./ч)
A21: 46116 | B21: — обучение персонала | C21: =G1*8*'Исходные данне'!E40 -> 1200000 | F21: =SUM(C21:E21) -> 1200000 | G21: SkillStaff (тренер Middle)
A23: 5 | B23: OpEx: ФОТ поддержки | C23: =3*'Исходные данне'!E28*12 -> 5400000 | D23: =C23 -> 5400000 | E23: =D23 -> 5400000 | F23: =SUM(C23:E23) -> 16200000 | G23: Контекст-2 (Store Ops)
A25: 6 | B25: OpEx: Каналы связи | C25: =G1*'Исходные данне'!E58*12 -> 3000000 | D25: =C25 -> 3000000 | E25: =D25 -> 3000000 | F25: =SUM(C25:E25) -> 9000000 | G25: Билайн бизнес
A27: 7 | B27: Скрытые затраты | C27: =SUM(C28:C31) -> 250000 | D27: =SUM(D28:D31) -> 0 | E27: =SUM(E28:E31) -> 500000 | F27: =SUM(C27:E27) -> 750000 | G27: Оценка + Шаг 1, раздел 8
A28: 46029 | B28: Простой магазина | C28: ='Исходные данне'!E63*5 -> 250000 | F28: =SUM(C28:E28) -> 250000 | G28: Артефакт-3 (INC-8433)
A29: 46060 | B29: Утилизация серверов | E29: ='Исходные данне'!E62*G1 -> 500000 | F29: =SUM(C29:E29) -> 500000 | G29: Шаг 1, п. 8.1
A30: 46088 | B30: Утилизация POS-компьютеров | F30: =SUM(C30:E30) -> 0 | G30: Шаг 1, п. 8.1
A31: 46119 | B31: Потери от обрыва связи (лояльность) | F31: =SUM(C31:E31) -> 0 | G31: Артефакт-3 (INC-8402)
A33: 8 | B33: Остаточная стоимость | C33: =SUM(C34:C37) -> 15948100 | D33: =SUM(D34:D37) -> 10252350 | E33: =SUM(E34:E37) -> 3417450 | G33: Расчёт
A34: 46030 | B34: Сервер локальный | C34: ='Расчёт остаточной стоимости'!D4*$G$1 -> 8400000 | D34: ='Расчёт остаточной стоимости'!E4*$G$1 -> 5400000 | E34: ='Расчёт остаточной стоимости'!F4*$G$1 -> 1800000 | G34: Лист "Расчёт остаточной стоимости" умножить на количество магазинов в расчёте
A35: 46061 | B35: POS-компьютер / моноблок | C35: ='Расчёт остаточной стоимости'!D5*$G$1 -> 2555000 | D35: ='Расчёт остаточной стоимости'!E5*$G$1 -> 1642500 | E35: ='Расчёт остаточной стоимости'!F5*$G$1 -> 547500 | G35: Лист "Расчёт остаточной стоимости" умножить на количество магазинов в расчёте
A36: 46089 | B36: Фискальный регистратор (ККТ) | C36: ='Расчёт остаточной стоимости'!D6*$G$1 -> 3243100 | D36: ='Расчёт остаточной стоимости'!E6*$G$1 -> 2084850 | E36: ='Расчёт остаточной стоимости'!F6*$G$1 -> 694950 | G36: Лист "Расчёт остаточной стоимости" умножить на количество магазинов в расчёте
A37: 46120 | B37: Банковский терминал | C37: ='Расчёт остаточной стоимости'!D7*$G$1 -> 1750000 | D37: ='Расчёт остаточной стоимости'!E7*$G$1 -> 1125000 | E37: ='Расчёт остаточной стоимости'!F7*$G$1 -> 375000 | G37: Лист "Расчёт остаточной стоимости" умножить на количество магазинов в расчёте
B39: ИТОГО годовые (1–7) | C39: =C4+C11+C14+C17+C23+C25+C27 -> 48853000 | D39: =D4+D11+D14+D17+D23+D25+D27 -> 9700000 | E39: =E4+E11+E14+E17+E23+E25+E27 -> 10200000 | F39: =SUM(C39:E39) -> 68753000
B40: Накопленные (1–7) | C40: =C39 -> 48853000 | D40: =C40+D39 -> 58553000 | E40: =D40+E39 -> 68753000
B41: Net TCO (накопленные − остаточная) | C41: =C40-C33 -> 32904900 | D41: =D40-D33 -> 48300650 | E41: =E40-E33 -> 65335550

Sheet TO-BE — TCO по статьям
A1: TCO TO-BE | B1: Количество магазинов | G1: ='AS-IS — TCO за 3 года'!G1 -> 100
A3: № | B3: Статья | C3: Год 1 | D3: Год 2 | E3: Год 3 | F3: Итого | G3: Источник | H3: Формула расчёта
A4: 1 | B4: CapEx: Оборудование | C4: =SUM(C5:C9) -> 14053000 | D4: =SUM(D5:D9) -> 0 | E4: =SUM(E5:E9) -> 0 | F4: =SUM(C4:E4) -> 14053000 | H4: Сумма статей 1.1–1.6
A5: 1.1 | B5: Планшет (Cloud POS) | C5: ='Исходные данне'!E9*G1 -> 2500000 | F5: =SUM(C5:E5) -> 2500000 | G5: Шаг 1, п. 1.5 | H5: 100 × 25 000 ₽
A6: 1.2 | B6: Фискальный регистратор (ККТ) | C6: ='Исходные данне'!E10*G1 -> 4633000 | F6: =SUM(C6:E6) -> 4633000 | G6: Шаг 1, п. 1.6 | H6: 100 × 46 330 ₽
A7: 1.3 | B7: Фискальный накопитель (ФН-15) | C7: ='Исходные данне'!E11*G1 -> 920000 | F7: =SUM(C7:E7) -> 920000 | G7: Шаг 1, п. 1.7 | H7: 100 × 9 200 ₽
A8: 1.4 | B8: Edge Node (HAL Agent) | C8: =G1*'Исходные данне'!E12 -> 3500000 | F8: =SUM(C8:E8) -> 3500000 | G8: Шаг 1, п. 1.8 | H8: 100 × 35 000 ₽
A9: 1.5 | B9: Банковский терминал | C9: =G1*'Исходные данне'!E13 -> 2500000 | F9: =SUM(C9:E9) -> 2500000 | G9: Шаг 1, п. 1.9 | H9: 100 × 25 000 ₽
A11: 2 | B11: CapEx: Разработка | C11: =SUM(C12:C16) -> 14050000 | D11: =SUM(D12:D16) -> 0 | E11: =SUM(E12:E16) -> 0 | F11: =SUM(C11:E11) -> 14050000 | H11: Сумма статей 2.1–2.5
A12: 2.1 | B12: Разработка HAL Agent | C12: =2000*'Исходные данне'!E51 -> 6000000 | F12: =SUM(C12:E12) -> 6000000 | G12: Шаг 1, п. 6.1 | H12: 2 000 ч × 3 000 ₽
A13: 2.2 | B13: Разработка Payment Gateway | C13: =1500*'Исходные данне'!E52 -> 4500000 | F13: =SUM(C13:E13) -> 4500000 | G13: Шаг 1, п. 6.2 | H13: 1 500 ч × 3 000 ₽
A14: 2.3 | B14: Разработка AI SKU Matching | C14: =1000*'Исходные данне'!E53 -> 3000000 | F14: =SUM(C14:E14) -> 3000000 | G14: Шаг 1, п. 6.3 | H14: 1 000 ч × 3 000 ₽
A15: 2.4 | B15: Миграция в облако | C15: ='Исходные данне'!E54 -> 500000 | F15: =SUM(C15:E15) -> 500000 | G15: Шаг 1, п. 6.4 | H15: Консалтинг ITGLOBAL.COM
A16: 2.5 | B16: Обучение ИТ-команды | C16: =5*'Исходные данне'!E55 -> 50000 | F16: =SUM(C16:E16) -> 50000 | G16: Шаг 1, п. 6.5 | H16: 5 чел × 10 000 ₽
A18: 3 | B18: OpEx: Облачные подписки | C18: =SUM(C19:C27) -> 2945520 | D18: =SUM(D19:D27) -> 2945520 | E18: =SUM(E19:E27) -> 2945520 | F18: =SUM(C18:E18) -> 8836560 | H18: Сумма статей 3.1–3.9
A19: 3.1 | B19: ITSM / Monitoring | C19: =G1*12*'Исходные данне'!E18 -> 1800000 | D19: =C19 -> 1800000 | E19: =D19 -> 1800000 | F19: =SUM(C19:E19) -> 5400000 | G19: ServiceNow / Datadog | H19: 100 × 12 × 1 500 ₽
A20: 3.2 | B20: Виртуальные машины (Cloud Backend) | C20: =5*12*'Исходные данне'!E45 -> 270000 | D20: =C20 -> 270000 | E20: =D20 -> 270000 | F20: =SUM(C20:E20) -> 810000 | G20: 5VM
A21: 3.3 | B21: API Gateway | C21: ='Исходные данне'!E47*12 -> 180000 | D21: =C21 -> 180000 | E21: =D21 -> 180000 | F21: =SUM(C21:E21) -> 540000
A22: 3.4 | B22: Объектное хранилище (бэкапы) | C22: =12*'Исходные данне'!E46*'Исходные данне'!D46 -> 30000 | D22: =C22 -> 30000 | E22: =D22 -> 30000 | F22: =SUM(C22:E22) -> 90000
A23: 3.5 | B23: Payment Gateway | C23: ='Исходные данне'!E17*12 -> 30000 | D23: =C23 -> 30000 | E23: =D23 -> 30000 | F23: =SUM(C23:E23) -> 90000
A24: 3.6 | B24: Managed PostgreSQL | C24: ='Исходные данне'!E19*12 -> 15288 | D24: =C24 -> 15288 | E24: =D24 -> 15288 | F24: =SUM(C24:E24) -> 45864
A25: 3.7 | B25: Managed Kafka | C25: ='Исходные данне'!E20*12 -> 14232 | D25: =C25 -> 14232 | E25: =D25 -> 14232 | F25: =SUM(C25:E25) -> 42696
A26: 3.8 | B26: Managed Redis | C26: ='Исходные данне'!E21*12 -> 6000 | D26: =C26 -> 6000 | E26: =D26 -> 6000 | F26: =SUM(C26:E26) -> 18000
A27: 3.9 | B27: iPaaS | C27: ='Исходные данне'!E48*12 -> 600000 | D27: =C27 -> 600000 | E27: =D27 -> 600000 | F27: =SUM(C27:E27) -> 1800000
A29: 4 | B29: OpEx: ФОТ онбординга | C29: =SUM(C30:C31) -> 1400000 | D29: =SUM(D30:D31) -> 0 | E29: =SUM(E30:E31) -> 0 | F29: =SUM(F30:F31) -> 1400000 | H29: Сумма статей 4.1–4.2
A30: 4.1 | B30: Ручной маппинг SKU (TO-BE) | C30: =G1*'Исходные данне'!E39*4 -> 200000 | F30: =SUM(C30:E30) -> 200000 | G30: Шаг 1, п. 3.3 | H30: 100 × 4 ч × 500 ₽
A31: 4.2 | B31: Обучение персонала | C31: =G1*'Исходные данне'!E40*8 -> 1200000 | F31: =SUM(C31:E31) -> 1200000 | G31: Шаг 1, п. 4.5 | H31: 100 × 8 ч × 1 500 ₽
A33: 5 | B33: OpEx: ФОТ поддержки | C33: =SUM(C34) -> 3600000 | D33: =SUM(D34) -> 3600000 | E33: =SUM(E34) -> 3600000 | F33: =SUM(F34) -> 10800000 | H33: Сумма статей 5.1
A34: 5.1 | B34: Store Ops (2 FTE) | C34: =2*'Исходные данне'!E28*12 -> 3600000 | D34: =C34 -> 3600000 | E34: =D34 -> 3600000 | F34: =SUM(C34:E34) -> 10800000 | H34: 2 FTE × 12 мес × 150 000 ₽
A36: 6 | B36: OpEx: Каналы связи | C36: =SUM(C37:C38) -> 4200000 | D36: =SUM(D37:D38) -> 4200000 | E36: =SUM(E37:E38) -> 4200000 | F36: =SUM(C36:E36) -> 12600000 | H36: Сумма статей 6.1–6.2
A37: 6.1 | B37: Интернет (основной канал) | C37: =G1*12*'Исходные данне'!E58 -> 3000000 | D37: 3000000 | E37: 3000000 | F37: =SUM(C37:E37) -> 9000000 | G37: Билайн бизнес | H37: 100 × 12 × 2 500 ₽
A38: 6.2 | B38: Резервный канал (LTE) | C38: =G1*12*'Исходные данне'!E59 -> 1200000 | D38: 1200000 | E38: 1200000 | F38: =SUM(C38:E38) -> 3600000 | G38: Оценка | H38: 100 × 12 × 1 000 ₽
A40: 7 | B40: Скрытые затраты | C40: =SUM(C41:C44) -> 0 | D40: =SUM(D41:D44) -> 0 | E40: =SUM(E41:E44) -> 0 | F40: =SUM(C40:E40) -> 0 | H40: Сумма статей 7.1–7.4
A41: 7.1 | B41: Простой магазина | G41: Offline-first | H41: Магазин работает без связи
A42: 7.2 | B42: Утилизация серверов | G42: Контекст-7 | H42: Локальные серверы ликвидированы
A43: 7.3 | B43: Утилизация POS | G43: Контекст-7 | H43: Планшеты в эксплуатации
A44: 7.4 | B44: Потери от обрыва связи | G44: Шаг 1, п. 8.3 | H44: Offline-кэш + reconciliation
A46: 8 | B46: Остаточная стоимость | C46: =SUM(C47:C50) -> 9193100 | D46: =SUM(D47:D50) -> 5909850 | E46: =SUM(E47:E50) -> 1969950 | G46: Расчёт | H46: Детализация
A47: 8.1 | B47: Планшет (Cloud POS) | C47: ='Расчёт остаточной стоимости'!D15*$G$1 -> 1750000 | D47: ='Расчёт остаточной стоимости'!E15*$G$1 -> 1125000 | E47: ='Расчёт остаточной стоимости'!F15*$G$1 -> 375000 | G47: 70/45/15% | H47: 100 × (17 500 / 11 250 / 3 750)
A48: 8.2 | B48: Фискальный регистратор | C48: ='Расчёт остаточной стоимости'!D16*$G$1 -> 3243100 | D48: ='Расчёт остаточной стоимости'!E16*$G$1 -> 2084850 | E48: ='Расчёт остаточной стоимости'!F16*$G$1 -> 694950 | G48: 70/45/15% | H48: 100 × (32 431 / 20 849 / 6 950)
...
